Workbook

Sheet README
A1: BALLOON PROGRAMME — BILL OF MATERIALS
A2: Version 1 and version 2 of the stratospheric balloon payload. Companion to the 18-month study plan and the teaching contract.
B4: Read these two sheets first
B5: Rules and findings | C5: Six things that change what you buy, including the radio licence that gates the link design and the documented flight that challenges version 1 as specified. Read it before ordering anything.
B6: Budget rollup | C6: Every sheet totalled, with contingency, measured against your 5 to 6 lakh budget. It re-totals when you change a price anywhere in the workbook.
B7: How to use the workbook
B8: Blue figures are yours to edit | C8: Quantity, unit cost and mass are blue because they are inputs. Black cells are formulas and green cells pull from another sheet. Do not overwrite them.
B9: Yellow cells are the assumptions | C9: The contingency rate and your budget range. Change them and the rollup follows.
B10: The Status column is your purchase tracker | C10: Set each line to Owned, To buy, Ordered, Received or Deferred as you go. Nothing in the workbook depends on it, so use whatever words suit you.
B11: Hover for the warnings | C11: Where an item name carries a small red marker there is a comment on it, usually a failure mode or a reason the obvious part is the wrong one.
B12: Fill the mass column from measurements | C12: Weigh parts as they arrive rather than trusting listings. Payload mass sets balloon size, and the balloon and gas are the largest consumable in the programme.
B13: What this is not
B14: Not a quotation | C14: Three figures are grounded in sources named on the findings sheet. The rest are planning estimates, each marked in the price basis column. Re-quote before ordering.
B15: Not a final design | C15: You said version 1 and version 2 are rough ideas and that the architecture comes later. This is the budget envelope for those ideas, built so it survives the architecture changing.
B16: Not a substitute for the mass and power budgets | C16: Modules 5, 6 and 7 of the study plan are where these numbers get defended. The workbook funds that work; it does not replace it.
B17: Sheets in this workbook
B18: Already owned | C18: Your existing hardware at zero cost, with the three caveats that matter before any of it flies.
B19: V1 BOM | C19: Version 1 in full, by subsystem: lift and recovery, airframe, propulsion, flight control, compute and imaging, sensors, communications, power and thermal, structure.
B20: V2 additions | C20: Only what changes for version 2. The programme total is version 1 plus this sheet.
B21: Ground station | C21: Built in month 2 and reused for every flight and into the satellite work.
B22: Test and tools | C22: Bought once, used across both flights. Two lines marked deferred.
B23: Per flight costs | C23: Recurring costs per launch attempt, excluding the balloon and gas.
B24: Fees and permissions | C24: The cheapest and slowest part of the programme. Two lines gate the flight entirely.
B26: Prepared October 2026. Prices and regulations both change; re-verify before committing money.

Sheet Budget rollup
A1: BALLOON PROGRAMME — BUDGET ROLLUP
A2: Planning estimates in INR, not quotations. Every figure traces to a line on a sheet in this workbook; change a price there and this page re-totals. Version 1 and version 2 are concept designs, not final architecture, so treat this as the budget envelope rather than a purchase order.
B4: Line | C4: Cost (INR) | D4: Mass (g) | E4: Note
B5: Already in hand | C5: ='Already owned'!F15 -> 0 | D5: ='Already owned'!H16 -> 357 | E5: Credited at zero. Three items need checking or replacing before flight.
B6: Version 1 flight hardware | C6: ='V1 BOM'!F63 -> 315140 | D6: ='V1 BOM'!H64 -> 4450 | E6: Includes the balloon, gas and a spare balloon for flight 1. Mass column shows flying payload only.
B7: Version 2 additions | C7: ='V2 additions'!F14 -> 207400 | D7: ='V2 additions'!H15 -> 1660 | E7: Deltas only. Reuses the version 1 avionics, radios and power system.
B8: Ground station | C8: ='Ground station'!F14 -> 64500 | E8: Reused across every flight and into the satellite work.
B9: Test equipment and tools | C9: ='Test and tools'!F18 -> 117000 | E9: Bought once. Includes two lines marked deferred.
B10: Per-flight recurring costs | C10: ='Per flight costs'!F11*3 -> 52500 | E10: Multiplied by three launch attempts, not two flights. Weather scrubs happen.
B11: Fees, licences and permissions | C11: ='Fees and permissions'!F12 -> 37000 | E11: Two lines are unresolved and left at zero. See the Rules sheet.
B12: SUBTOTAL | C12: =SUM(C5:C11) -> 793540 | E12: New spending before contingency.
B13: Contingency rate | C13: 0.2 | E13: Edit this. 20% is the minimum for a first-of-its-kind build; 30% is more honest.
B14: Contingency | C14: =C12*C13 -> 158708 | E14: Breakage, re-orders, shipping, customs and the parts you have not thought of.
B15: PROGRAMME TOTAL | C15: =C12+C14 -> 952248
B17: YOUR STATED BUDGET
B18: Budget, low | C18: 500000
B19: Budget, high | C19: 600000
B20: Headroom against the high budget | C20: =C19-C15 -> -352248 | E20: Negative means the programme as specified does not fit. Cut deferred lines first, then scope.
B21: Spent as a share of the high budget | C21: =IFERROR(C15/C19,0) -> 1.58708
B23: The one calculation to do before you order anything
B24: Total payload mass sets the balloon size, and the balloon and its gas are the largest consumable in the programme. Fill in the mass column on the version 1 sheet from measured parts, not listings, and read the total at the bottom. If it comes out above roughly 3 kg, re-quote the balloon one size up and add a cylinder of helium before trusting this rollup. That is module 5 (M05-B01) doing real work.
B26: Version 1 flying payload mass | C26: ='V1 BOM'!H64 -> 4450 | D26: grams
B27: That is the sum of every line marked Y in the Flies column, so it excludes the balloon, the gas, the spare airframe and bulk consumable stock. Treat it as an upper bound until you have weighed the parts: some lines, such as hand warmers and fasteners, are stocked in quantities larger than one flight uses. Compare it against the 1,300 g of the documented glider flight on the findings sheet before you accept it.

Sheet Fit to budget
A1: MAKING IT FIT — THE PROGRAMME AS SPECIFIED IS OVER BUDGET
A2: Version 1 and version 2 as specified do not fit 5 to 6 lakh. This sheet shows the gap and a cut path that does fit, in the order I would cut. Nothing here is deleted from the other sheets, so you can take the cuts you accept and leave the rest.
B4: THE GAP
B5: Programme total as specified | C5: ='Budget rollup'!C15 -> 952248 | E5: Including contingency at the rollup rate.
B6: Your budget, high end | C6: ='Budget rollup'!C19 -> 600000 | E6: As you stated it.
B7: Gap | C7: ='Budget rollup'!C19-'Budget rollup'!C15 -> -352248 | E7: Negative means over budget.
B8: Over by | C8: =IFERROR('Budget rollup'!C15/'Budget rollup'!C19-1,0) -> 0.58708 | E8: As a share of your budget.
B10: THE CUT PATH, IN ORDER
B11: Cut | C11: Saves (INR) | D11: Running total | E11: What it costs you
B12: Defer the oscilloscope | C12: 30000 | D12: =SUM(C12:C12) -> 30000 | E12: Your logic analyser covers the digital bus debugging you will actually do. Buy a scope when you can name the measurement you cannot make without one.
B13: Defer the 14-bit SDR | C13: 24000 | D13: =SUM(C12:C13) -> 54000 | E13: Start with the RTL-SDR v5 you own. Buy the better receiver when a measurement shows the receiver is your limiting factor, not before.
B14: Drop the chest freezer, use dry ice | C14: 18000 | D14: =SUM(C12:C14) -> 72000 | E14: Dry ice reaches stratospheric-class cold; the freezer only reaches about minus 20. Keep the dry ice line and lose the appliance.
B15: One satellite tracker, not two | C15: 32000 | D15: =SUM(C12:C15) -> 104000 | E15: Carry it over from flight 1 to flight 2 rather than buying a second. You lose redundancy on the long-range link, so keep two independent GSM trackers.
B16: Defer the version 2 imaging upgrade | C16: 35000 | D16: =SUM(C12:C16) -> 139000 | E16: Fly version 2 on the version 1 cameras. Specify the upgrade from what flight 1 and flight 2 actually show you need, which is the honest order anyway.
B17: Defer the calibrated sensor set to flight 3 | C17: 18000 | D17: =SUM(C12:C17) -> 157000 | E17: The reusable-radiosonde claim needs traceable instruments, but it does not need them before you have proven the vehicle returns.
B18: One spare balloon across both flights, not two | C18: 26000 | D18: =SUM(C12:C18) -> 183000 | E18: Buy three balloons rather than four. You accept that a second burst on fill day ends that campaign.
B19: Halve the unallocated version 2 spares | C19: 12500 | D19: =SUM(C12:C19) -> 195500 | E19: From 25,000 to 12,500. Thin, and the first thing to restore if flight 1 goes badly.
B20: Trim third launch attempt allowance | C20: 17500 | D20: =SUM(C12:C20) -> 213000 | E20: Budget two launch attempts rather than three. You accept that a second weather scrub costs you money you have not set aside.
B21: TOTAL SAVED | C21: =SUM(C12:C20) -> 213000
B23: AFTER THE CUTS
B24: Subtotal after cuts | C24: ='Budget rollup'!C12-C21 -> 580540 | E24: New spending before contingency.
B25: Contingency at the same rate | C25: =C24*'Budget rollup'!C13 -> 116108 | E25: Edit the rate on the rollup sheet.
B26: Revised programme total | C26: =C24+C25 -> 696648 | E26: Compare this with your budget.
B27: Headroom against the high budget | C27: ='Budget rollup'!C19-C26 -> -96648 | E27: Positive means it fits.
B28: Share of the high budget | C28: =IFERROR(C26/'Budget rollup'!C19,0) -> 1.16108 | E28: Under 100% means it fits.
B30: THE CUTS ARE NOT ENOUGH
B31: Taking every cut above still leaves the programme over your budget. That is the honest result, and it points at one conclusion: two full flights plus a complete ground station plus a test bench plus the licences is roughly a seven lakh programme, not a six lakh one. The way to fit six lakh is not to shave it further. It is to stop after version 1 and let version 2 fall into the next budget cycle, which is also the right engineering order, since version 2 should be specified from what version 1 actually teaches you.
B33: OPTION: SHAKEDOWN PLUS VERSION 1, VERSION 2 DEFERRED
B34: Version 2 spending removed | C34: =-('V2 additions'!F14-32000-35000-18000-26000-12500) -> -83900 | E34: The version 2 sheet after its share of the cuts above. Deferred, not cancelled.
B35: Second helium fill, for the shakedown flight | C35: =3*2800 -> 8400 | E35: The version 1 sheet funds three cylinders, which is one fill. Two flights need two fills.
B36: Subtotal | C36: =C24+C34+C35 -> 505040 | E36: Cut path applied, version 2 deferred, second gas fill added.
B37: Contingency at the same rate | C37: =C36*'Budget rollup'!C13 -> 101008 | E37: Unchanged rate.
B38: PROGRAMME TOTAL, this option | C38: =C36+C37 -> 606048 | E38: Two flights, full ground station, test bench and licences. No spare balloon retained.
B39: Headroom against the high budget | C39: ='Budget rollup'!C19-C38 -> -6048 | E39: Positive means it fits.
B40: Share of the high budget | C40: =IFERROR(C38/'Budget rollup'!C19,0) -> 1.01008 | E40: Under 100% means it fits.
B41: One caveat on that total: it funds two balloons and two fills, which the shakedown and version 1 consume between them. It retains no spare balloon. If a balloon bursts on fill day, that campaign stops until you buy another, at roughly 26,000 rupees plus gas. Decide deliberately whether you are carrying that risk or budgeting it.
B43: The cheaper option I would actually take
B44: Before either of these flights, fly a shakedown: one balloon, one parachute, two independent trackers, a camera and the sensor board. No glider, no propellers, no return to base. It costs roughly a balloon, three cylinders of gas and the trackers, and it buys you the one thing no calculation gives you, which is what the winds over Gujarat actually do to a payload descending from 35 km. A documented autonomous glider team aimed for a 30 km release and settled for 10 km for exactly that reason. Fly the cheap one first and the expensive vehicle second, and the odds of recovering the expensive vehicle go up sharply.
B46: Shakedown flight, rough cost | C46: 45000 | E46: Balloon, gas, parachute, rigging, two GSM trackers and the chase. Re-quote it; the figure is an estimate.

Sheet V1 BOM
A1: VERSION 1 — BILL OF MATERIALS
A2: Version 1 as specified: ~35 km, camera, sensors, live telemetry and streaming, wings for controlled descent, propellers deployed below ~10 km for powered return to base. Prices are planning estimates in INR and must be re-quoted at purchase time. Blue cells are yours to edit. Mass drives balloon size, so fill the mass column before ordering the balloon.
A4: Ref | B4: Item | C4: Why this one / spec | D4: Qty | E4: Unit cost (INR) | F4: Line cost (INR) | G4: Mass each (g) | H4: Line mass (g) | I4: Flies? | J4: Price basis | K4: Where to buy | L4: Status
A5: LIFT & RECOVERY — the consumable half of every flight
A6: V1-01 | B6: Sounding balloon, 3000 g latex | C6: Sized for a ~3 kg payload to 33–35 km. A 2000 g balloon tops out near 2 kg; confirm against your own mass budget (module 5, M05-B01) before ordering. | D6: 1 | E6: 26000 | F6: =D6*E6 -> 26000 | G6: 3000 | H6: =D6*G6 -> 3000 | I6: N | J6: Estimate — verify with supplier | K6: Pawan Exports (India) or import | L6: To buy
A7: V1-02 | B7: Sounding balloon, spare | C7: One spare. A burst or mishandled balloon on fill day otherwise ends the campaign. | D7: 1 | E7: 26000 | F7: =D7*E7 -> 26000 | G7: 3000 | H7: =D7*G7 -> 3000 | I7: N | J7: Estimate — verify with supplier | K7: Same as above | L7: To buy
A8: V1-03 | B8: Helium, balloon grade, 7 m³ cylinder | C8: About 14–17 m³ of fill for a 3 kg payload with adequate free lift, so three cylinders. Industrial balloon-grade is adequate; research grade is not needed. | D8: 3 | E8: 2800 | F8: =D8*E8 -> 8400 | I8: N | J8: Verified: ₹2,300/7 m³ cylinder listed on IndiaMART (Jaipur, 2026) | K8: Local industrial gas supplier | L8: To buy
A9: V1-04 | B9: Cylinder regulator, fill hose and nozzle | C9: Reusable across flights. Must match the cylinder valve standard your supplier uses. | D9: 1 | E9: 10000 | F9: =D9*E9 -> 10000 | I9: N | J9: Estimate | K9: Industrial gas supplier | L9: To buy
A10: V1-05 | B10: Parachute, 1.8 m ripstop nylon | C10: Independent of the glider. If the glider fails to release or its control fails, this is what stops the payload becoming a falling object. | D10: 1 | E10: 6000 | F10: =D10*E10 -> 6000 | G10: 350 | H10: =D10*G10 -> 350 | I10: Y | J10: Estimate | K10: RC / rocketry supplier | L10: To buy
A11: V1-06 | B11: Rigging set: cord, swivels, carabiners, load tape | C11: 50 m braided nylon, rated well above payload mass, plus swivels to stop the train spinning. | D11: 1 | E11: 2500 | F11: =D11*E11 -> 2500 | G11: 250 | H11: =D11*G11 -> 250 | I11: N | J11: Estimate | K11: Local / hardware | L11: To buy
A12: V1-07 | B12: Nichrome cutdown and relay | C12: Releases the glider from the balloon train at the chosen altitude. The documented Rutgers glider flight used exactly this method. | D12: 2 | E12: 1200 | F12: =D12*E12 -> 2400 | G12: 40 | H12: =D12*G12 -> 80 | I12: Y | J12: Method verified from published glider flight | K12: Electronics supplier | L12: To buy
A13: AIRFRAME — the glider that does the real work of getting home
A14: V1-08 | B14: Glider airframe, 1.6–2.0 m span | C14: EPP or foamboard with carbon spars. The published 10 km glider drop was a homemade foamcore body at about 1300 g all-in and flew 196 km. | D14: 1 | E14: 15000 | F14: =D14*E14 -> 15000 | G14: 700 | H14: =D14*G14 -> 700 | I14: Y | J14: Mass verified from published flight (≈1300 g total vehicle) | K14: RC supplier / self-built | L14: To buy
A15: V1-09 | B15: Glider airframe, second unit | C15: For drop testing. The published flight made six test drops from a quadcopter before the balloon flight. | D15: 1 | E15: 15000 | F15: =D15*E15 -> 15000 | G15: 700 | H15: =D15*G15 -> 700 | I15: N | J15: Practice verified from published flight | K15: Same as above | L15: To buy
A16: V1-10 | B16: Carbon tube and rod spar set | C16: Wing spar and tail boom. Carbon keeps stiffness at low temperature where foam alone goes floppy. | D16: 1 | E16: 4000 | F16: =D16*E16 -> 4000 | G16: 120 | H16: =D16*G16 -> 120 | I16: Y | J16: Estimate | K16: RC supplier | L16: To buy
A17: V1-11 | B17: Control surface hardware: horns, linkages, hinges, film | C17: Consumable. Buy twice what you think you need. | D17: 1 | E17: 3500 | F17: =D17*E17 -> 3500 | G17: 80 | H17: =D17*G17 -> 80 | I17: N | J17: Estimate | K17: RC supplier | L17: To buy
A18: V1-12 | B18: Servos, metal gear digital, low-temperature rated | C18: Four: two elevons or aileron/elevator, one rudder, one spare channel. Specify a rated operating temperature below −40 °C. | D18: 4 | E18: 2500 | F18: =D18*E18 -> 10000 | G18: 60 | H18: =D18*G18 -> 240 | I18: Y | J18: Estimate | K18: RC supplier | L18: To buy
A19: V1-13 | B19: Airspeed sensor and pitot tube | C19: The flight controller needs airspeed, not just GPS ground speed, to hold a glide at altitude where true airspeed and indicated airspeed diverge sharply. | D19: 1 | E19: 4000 | F19: =D19*E19 -> 4000 | G19: 30 | H19: =D19*G19 -> 30 | I19: Y | J19: Estimate | K19: Drone supplier | L19: To buy
A20: PROPULSION — only useful below about 10 km
A21: V1-14 | B21: Propeller set, folding, 11–13 inch, assorted pitch | C21: Air at 10 km is roughly a quarter of sea-level density, so the same motor needs a larger, higher-pitch prop to produce the same thrust. Buy a range and test. | D21: 1 | E21: 3500 | F21: =D21*E21 -> 3500 | G21: 60 | H21: =D21*G21 -> 60 | I21: Y | J21: Density figure from the standard atmosphere | K21: RC supplier | L21: To buy
A22: V1-15 | B22: Brushless motor, lower KV alternative | C22: A second motor option with lower KV and a bigger prop is usually more efficient at altitude than spinning a small prop faster. | D22: 1 | E22: 3000 | F22: =D22*E22 -> 3000 | G22: 70 | H22: =D22*G22 -> 70 | I22: Y | J22: Estimate | K22: RC supplier | L22: To buy
A23: V1-16 | B23: Propeller deployment mechanism | C23: Folding props self-deploy under rotation; a servo-held latch keeps them stowed during ascent and descent. | D23: 1 | E23: 2500 | F23: =D23*E23 -> 2500 | G23: 80 | H23: =D23*G23 -> 80 | I23: Y | J23: Estimate | K23: Self-built / 3D printed | L23: To buy
A24: V1-17 | B24: Spare motor and ESC | C24: Props and motors are the parts most likely to be damaged on landing. | D24: 1 | E24: 3500 | F24: =D24*E24 -> 3500 | G24: 120 | H24: =D24*G24 -> 120 | I24: N | J24: Estimate | K24: RC supplier | L24: To buy
A25: FLIGHT CONTROL & NAVIGATION
A26: V1-18 | B26: Flight controller, Pixhawk class | C26: The published glider used a Pixhawk with GPS, commanded over MAVLink by a Raspberry Pi Zero, and landed about 10 m from its target waypoint. | D26: 1 | E26: 18000 | F26: =D26*E26 -> 18000 | G26: 40 | H26: =D26*G26 -> 40 | I26: Y | J26: Architecture verified from published glider flight | K26: Drone supplier | L26: To buy
A27: V1-19 | B27: GPS module, altitude-capable u-blox M8/M10 | C27: Primary navigation. Must be set to the airborne dynamic model. The u-blox 6/7/8 family combines its altitude and speed limits with AND logic, so it keeps working above 18 km while under 515 m/s. | D27: 1 | E27: 5000 | F27: =D27*E27 -> 5000 | G27: 15 | H27: =D27*G27 -> 15 | I27: Y | J27: Verified: UKHAS GPS module guide | K27: Electronics supplier | L27: To buy
A28: V1-20 | B28: GPS module, secondary | C28: Independent of the primary, ideally a different model. Losing position means losing the vehicle. | D28: 1 | E28: 4000 | F28: =D28*E28 -> 4000 | G28: 15 | H28: =D28*G28 -> 15 | I28: Y | J28: Estimate | K28: Electronics supplier | L28: To buy
A29: V1-21 | B29: External magnetometer / compass | C29: Away from the motor and power wiring, or the heading will be wrong exactly when the propellers run. | D29: 1 | E29: 2200 | F29: =D29*E29 -> 2200 | G29: 20 | H29: =D29*G29 -> 20 | I29: Y | J29: Estimate | K29: Drone supplier | L29: To buy
A30: COMPUTE & IMAGING
A31: V1-22 | B31: Camera module, global shutter, nadir | C31: Global shutter avoids the rolling-shutter smear a swinging payload produces. Nadir view is the one that georeferences cleanly. | D31: 1 | E31: 8000 | F31: =D31*E31 -> 8000 | G31: 40 | H31: =D31*G31 -> 40 | I31: Y | J31: Estimate | K31: Electronics supplier | L31: To buy
A32: V1-23 | B32: Camera module, horizon | C32: The horizon shot is what people actually want to see, and it is useful for attitude verification after the flight. | D32: 1 | E32: 6000 | F32: =D32*E32 -> 6000 | G32: 40 | H32: =D32*G32 -> 40 | I32: Y | J32: Estimate | K32: Electronics supplier | L32: To buy
A33: V1-24 | B33: Lens set, wide and narrow | C33: Field of view sets your swath; focal length sets your ground resolution. This is module 11 (M11-A01) made physical. | D33: 1 | E33: 5000 | F33: =D33*E33 -> 5000 | G33: 60 | H33: =D33*G33 -> 60 | I33: Y | J33: Estimate | K33: Optics supplier | L33: To buy
A34: V1-25 | B34: High-endurance microSD cards, 128 GB | C34: Onboard recording is the guaranteed data path. The radio link is a bonus, not the record. | D34: 3 | E34: 1500 | F34: =D34*E34 -> 4500 | G34: 2 | H34: =D34*G34 -> 6 | I34: N | J34: Estimate | K34: Any retailer | L34: To buy
A35: V1-26 | B35: Heatsink and thermal pads for the Orange Pi | C35: Running a model on the NPU in a sealed insulated box is a thermal problem, not only a compute one (M16-B04). | D35: 1 | E35: 1200 | F35: =D35*E35 -> 1200 | G35: 60 | H35: =D35*G35 -> 60 | I35: Y | J35: Estimate | K35: Electronics supplier | L35: To buy
A36: SENSORS
A37: V1-27 | B37: Barometric pressure sensor, MS5611 or BMP390 class | C37: Pressure at 35 km is about 5–6 hPa. A common BMP280 bottoms out near 300 hPa, which is only about 9 km, so it would stop reading three quarters of the way up. | D37: 2 | E37: 2000 | F37: =D37*E37 -> 4000 | G37: 2 | H37: =D37*G37 -> 4 | I37: Y | J37: Pressure figure from the standard atmosphere | K37: Electronics supplier | L37: To buy
A38: V1-28 | B38: External air temperature probe, PT1000 with amplifier | C38: Radiation-shielded and mounted clear of the payload box, or you will measure the box rather than the atmosphere. | D38: 2 | E38: 3000 | F38: =D38*E38 -> 6000 | G38: 25 | H38: =D38*G38 -> 50 | I38: Y | J38: Estimate | K38: Instrumentation supplier | L38: To buy
A39: V1-29 | B39: Humidity sensor, SHT85 class | C39: Needed for the radiosonde-replacement story in version 2; worth flying in version 1 to characterise it. | D39: 1 | E39: 3500 | F39: =D39*E39 -> 3500 | G39: 5 | H39: =D39*G39 -> 5 | I39: Y | J39: Estimate | K39: Electronics supplier | L39: To buy
A40: V1-30 | B40: Thermistors for internal monitoring | C40: Six points: battery, each camera, the Orange Pi, the radio, and ambient inside the box. | D40: 8 | E40: 80 | F40: =D40*E40 -> 640 | G40: 2 | H40: =D40*G40 -> 16 | I40: Y | J40: Estimate | K40: Electronics supplier | L40: To buy
A41: COMMUNICATIONS — read the legal note on the Rules sheet before buying
...

Sheet Already owned
A1: ALREADY IN HAND
A2: Listed at zero cost so the programme total reflects only new spending. The caveat column matters more than the credit: three of these items need checking or replacing before they fly. Hover the item name where a comment marker appears.
A4: Ref | B4: Item | C4: Why this one / spec | D4: Qty | E4: Unit cost (INR) | F4: Line cost (INR) | G4: Mass each (g) | H4: Line mass (g) | I4: Flies? | J4: Price basis | K4: Where to buy | L4: Status
A5: ALREADY IN HAND — credited against the programme, with the caveats that matter
A6: ALR-01 | B6: Orange Pi 4 Pro 6 GB, 3 TOPS NPU | C6: Onboard compute and the GeoAI payload (modules 15 and 16). Benchmark it yourself; the advertised TOPS figure will not predict sustained throughput in a sealed warm box. | D6: 1 | E6: 0 | F6: =D6*E6 -> 0 | G6: 120 | H6: =D6*G6 -> 120 | I6: Y | J6: Owned | K6: — | L6: Owned
A7: ALR-02 | B7: Raspberry Pi Pico 2 W and LAFVIN kit | C7: Sensor and housekeeping microcontroller, independent of the main computer. Good practice: let the small reliable thing hold the telemetry. | D7: 1 | E7: 0 | F7: =D7*E7 -> 0 | G7: 15 | H7: =D7*G7 -> 15 | I7: Y | J7: Owned | K7: — | L7: Owned
A8: ALR-03 | B8: Nooelec RTL-SDR v5, SAWbird+ NOAA LNA, V-dipole | C8: Complete receive chain for weather satellite imagery. This is build step M24-A01 and needs nothing further. | D8: 1 | E8: 0 | F8: =D8*E8 -> 0 | I8: Y | J8: Owned | K8: — | L8: Owned
A9: ALR-04 | B9: BNO085 9-DOF IMU | C9: Attitude sensing for the pointing demonstration (M24-C06) and for the glider. | D9: 1 | E9: 0 | F9: =D9*E9 -> 0 | G9: 12 | H9: =D9*G9 -> 12 | I9: Y | J9: Owned | K9: — | L9: Owned
A10: ALR-05 | B10: NEO-7M GPS modules, two | C10: Usable as the secondary GPS. The u-blox 6/7/8 family keeps working above 18 km when set to the airborne dynamic model, but verify the setting survives a power cycle on these clone boards. | D10: 2 | E10: 0 | F10: =D10*E10 -> 0 | G10: 15 | H10: =D10*G10 -> 30 | I10: Y | J10: Owned — verify airborne mode persists | K10: — | L10: Owned
A11: ALR-06 | B11: A2212 1000KV motor, 30 A ESC, 1045 props | C11: Propulsion starting point. The 1045 prop is sized for sea level; expect to fit a larger, higher-pitch prop for 8–10 km. | D11: 1 | E11: 0 | F11: =D11*E11 -> 0 | G11: 120 | H11: =D11*G11 -> 120 | I11: Y | J11: Owned | K11: — | L11: Owned
A12: ALR-07 | B12: MG996R servos | C12: Bench and drop testing only. Not rated for stratospheric cold, and heavy at roughly 55 g each. | D12: 1 | E12: 0 | F12: =D12*E12 -> 0 | G12: 55 | H12: =D12*G12 -> 55 | I12: Y | J12: Owned — not flight rated | K12: — | L12: Owned
A13: ALR-08 | B13: BPW34 photodiodes, five | C13: Sun sensing for the sun-tracking demonstration (M24-C07) and the satellite attitude work in module 8. | D13: 5 | E13: 0 | F13: =D13*E13 -> 0 | G13: 1 | H13: =D13*G13 -> 5 | I13: Y | J13: Owned | K13: — | L13: Owned
A14: ALR-09 | B14: Logic analyser, 8 channel, 24 MHz | C14: I2C, SPI and UART debugging. Covers most of what you will need on the bench. | D14: 1 | E14: 0 | F14: =D14*E14 -> 0 | I14: Y | J14: Owned | K14: — | L14: Owned
A15: TOTAL | F15: =SUM(F6:F14) -> 0 | H15: =SUM(H6:H14) -> 357
A16: OF WHICH FLIES | H16: =SUMIF(I6:I14,"Y",H6:H14) -> 357 | J16: This is the mass that sizes the balloon.

Sheet V2 additions
A1: VERSION 2 — ADDITIONS AND CHANGES ONLY
A2: Version 2 reuses the version 1 avionics, radios, power system and ground station. Only the deltas are listed here, so the programme total is version 1 plus this sheet. Version 2 as discussed: a wide-area weather and imaging profile positioned as a reusable alternative to disposable radiosondes.
A4: Ref | B4: Item | C4: Why this one / spec | D4: Qty | E4: Unit cost (INR) | F4: Line cost (INR) | G4: Mass each (g) | H4: Line mass (g) | I4: Flies? | J4: Price basis | K4: Where to buy | L4: Status
A5: WHAT CHANGES FOR VERSION 2 — flown about two months after version 1
A6: V2-01 | B6: Airframe, third unit, longer range | C6: Version 2 trades the return-to-base demonstration for coverage: a wider wing and a better glide ratio buy range for the wide-area weather and imaging profile. | D6: 1 | E6: 25000 | F6: =D6*E6 -> 25000 | G6: 900 | H6: =D6*G6 -> 900 | I6: Y | J6: Estimate | K6: RC supplier / self-built | L6: To buy
A7: V2-02 | B7: Calibrated humidity and temperature sensor set | C7: For the reusable-radiosonde claim you need instruments you can defend against a reference, not hobby sensors. | D7: 1 | E7: 18000 | F7: =D7*E7 -> 18000 | G7: 60 | H7: =D7*G7 -> 60 | I7: Y | J7: Estimate — verify against instrument suppliers | K7: Instrumentation supplier | L7: To buy
A8: V2-03 | B8: Higher-resolution or multispectral camera | C8: The imaging half of the version 2 profile. Specify it from the ground resolution and swath you actually need, not from the highest number available (M11-C02). | D8: 1 | E8: 35000 | F8: =D8*E8 -> 35000 | G8: 120 | H8: =D8*G8 -> 120 | I8: Y | J8: Estimate | K8: Import / specialist | L8: To buy
A9: V2-04 | B9: Extended battery capacity | C9: A longer flight profile needs more energy. Re-run the energy balance rather than adding cells by feel (M06-C03). | D9: 1 | E9: 12000 | F9: =D9*E9 -> 12000 | G9: 500 | H9: =D9*G9 -> 500 | I9: Y | J9: Estimate | K9: As above | L9: To buy
A10: V2-05 | B10: Second satellite tracker | C10: Two independent long-range trackers once the flight profile takes the vehicle beyond easy reach. | D10: 1 | E10: 32000 | F10: =D10*E10 -> 32000 | G10: 80 | H10: =D10*G10 -> 80 | I10: Y | J10: Estimate | K10: Import | L10: To buy
A11: V2-06 | B11: Sounding balloon, 3000 g, and spare | C11: Two more balloons for flight 2 and its reflight margin. | D11: 2 | E11: 26000 | F11: =D11*E11 -> 52000 | G11: 3000 | H11: =D11*G11 -> 6000 | I11: N | J11: Estimate — verify with supplier | K11: Pawan Exports (India) or import | L11: To buy
A12: V2-07 | B12: Helium, 7 m³ cylinders, flight 2 | C12: Three cylinders again, assuming a similar payload mass. | D12: 3 | E12: 2800 | F12: =D12*E12 -> 8400 | I12: N | J12: Verified: ₹2,300/7 m³ listed on IndiaMART (Jaipur, 2026) | K12: Local gas supplier | L12: To buy
A13: V2-08 | B13: Spares and replacements from flight 1 lessons | C13: Reserved, unallocated. Every documented first flight produces a list of things to replace. | D13: 1 | E13: 25000 | F13: =D13*E13 -> 25000 | I13: N | J13: Allowance | K13: Various | L13: To buy
A14: TOTAL | F14: =SUM(F6:F13) -> 207400 | H14: =SUM(H6:H13) -> 7660
A15: OF WHICH FLIES | H15: =SUMIF(I6:I13,"Y",H6:H13) -> 1660 | J15: This is the mass that sizes the balloon.

Sheet Ground station
A1: GROUND STATION
A2: Reused across every flight and the most valuable thing you can build early. It turns link budgets, Doppler and pass planning from abstractions into measurements. Your RTL-SDR v5, SAWbird+ NOAA filter and V-dipole already cover weather satellite reception.
A4: Ref | B4: Item | C4: Why this one / spec | D4: Qty | E4: Unit cost (INR) | F4: Line cost (INR) | G4: Mass each (g) | H4: Line mass (g) | I4: Flies? | J4: Price basis | K4: Where to buy | L4: Status
A5: RECEIVE CHAIN — build this in month 2, long before anything flies
A6: GRO-01 | B6: Software defined radio, 14-bit class | C6: Your RTL-SDR v5 is 8-bit and adequate for weather satellite imagery. A 14-bit receiver gives real dynamic range for a weak payload downlink; the published balloon video build used one. | D6: 1 | E6: 24000 | F6: =D6*E6 -> 24000 | I6: Y | J6: Verified: receiver class named in published balloon video build | K6: Import | L6: To buy
A7: GRO-02 | B7: Low noise amplifier, 70 cm | C7: At the antenna, not at the radio. Cable loss ahead of the amplifier is unrecoverable. | D7: 1 | E7: 4000 | F7: =D7*E7 -> 4000 | I7: Y | J7: Estimate | K7: Electronics supplier | L7: To buy
A8: GRO-03 | B8: Yagi antenna, 70 cm, 7–11 element | C8: The published build tracked a balloon with a hand-held directional antenna on a tripod and held the link past 50 km. | D8: 1 | E8: 8000 | F8: =D8*E8 -> 8000 | I8: Y | J8: Verified: method from published balloon video build | K8: Import / self-built | L8: To buy
A9: GRO-04 | B9: Tripod with manual azimuth/elevation mount | C9: Manual tracking first. A rotator is an optimisation of something that already works. | D9: 1 | E9: 6000 | F9: =D9*E9 -> 6000 | I9: Y | J9: Estimate | K9: Photography / local | L9: To buy
A10: GRO-05 | B10: Low-loss coaxial cable, 20 m, with connectors | C10: LMR-400 class. Thin coax at 433 MHz over 20 m throws away much of what the antenna gained. | D10: 1 | E10: 5500 | F10: =D10*E10 -> 5500 | I10: Y | J10: Estimate | K10: Electronics supplier | L10: To buy
A11: GRO-06 | B11: LoRa 865 MHz receiver and antenna | C11: The licence-free telemetry path, independent of the amateur-band downlink. | D11: 1 | E11: 6000 | F11: =D11*E11 -> 6000 | I11: Y | J11: Estimate | K11: Electronics supplier | L11: To buy
A12: GRO-07 | B12: Field power: portable battery and inverter | C12: The ground station runs where the launch is, not where the mains is. | D12: 1 | E12: 11000 | F12: =D12*E12 -> 11000 | I12: Y | J12: Estimate | K12: Any retailer | L12: To buy
A13: GRO-08 | B13: Azimuth/elevation rotator | C13: DEFER. Only once manual tracking is proven to be the constraint. | D13: 1 | E13: 0 | F13: =D13*E13 -> 0 | I13: Y | J13: Deferred — set cost when you decide to buy | K13: Import | L13: Deferred
A14: TOTAL | F14: =SUM(F6:F13) -> 64500 | H14: =SUM(H6:H13) -> 0
A15: OF WHICH FLIES | H15: =SUMIF(I6:I13,"Y",H6:H13) -> 0 | J15: This is the mass that sizes the balloon.

Sheet Test and tools
A1: TEST EQUIPMENT & TOOLS
A2: Bought once, used across both flights and into the CubeSat work. Your 8-channel logic analyser already covers I2C, SPI and UART debugging.
A4: Ref | B4: Item | C4: Why this one / spec | D4: Qty | E4: Unit cost (INR) | F4: Line cost (INR) | G4: Mass each (g) | H4: Line mass (g) | I4: Flies? | J4: Price basis | K4: Where to buy | L4: Status
A5: BENCH — needed from month 4, when the payload starts coming together
A6: TES-01 | B6: Bench power supply, 0–30 V, 5 A, current limited | C6: For measuring real current draw per component, which is how a power budget gets built from measurements instead of datasheets (M06-C01). | D6: 1 | E6: 9000 | F6: =D6*E6 -> 9000 | I6: Y | J6: Estimate | K6: Electronics supplier | L6: To buy
A7: TES-02 | B7: Digital multimeter, good quality | C7: You will trust this instrument for every electrical decision. Buy one you can trust. | D7: 1 | E7: 5000 | F7: =D7*E7 -> 5000 | I7: Y | J7: Estimate | K7: Electronics supplier | L7: To buy
A8: TES-03 | B8: Temperature-controlled soldering station with hot air | C8: Hot air for the surface-mount sensor breakouts. | D8: 1 | E8: 9000 | F8: =D8*E8 -> 9000 | I8: Y | J8: Estimate | K8: Electronics supplier | L8: To buy
A9: TES-04 | B9: Precision scale, 0.1 g to 5 kg | C9: Mass budget work. Every gram changes the balloon sizing, so weigh the parts rather than trusting the listings. | D9: 1 | E9: 4500 | F9: =D9*E9 -> 4500 | I9: Y | J9: Estimate | K9: Any retailer | L9: To buy
A10: TES-05 | B10: Oscilloscope, 2 channel, 100 MHz | C10: DEFER if budget is tight. Your logic analyser covers the digital bus debugging you will do most often. | D10: 1 | E10: 30000 | F10: =D10*E10 -> 30000 | I10: Y | J10: Estimate | K10: Electronics supplier | L10: Deferred
A11: ENVIRONMENTAL TEST — needed from month 10, before flight 1
A12: TES-06 | B12: Vacuum chamber and two-stage pump | C12: Tests the payload at stratospheric pressure. Low pressure changes thermal behaviour, kills convective cooling, and finds sealing failures. | D12: 1 | E12: 22000 | F12: =D12*E12 -> 22000 | I12: Y | J12: Estimate | K12: Lab supplier | L12: To buy
A13: TES-07 | B13: Dry ice for cold testing, per campaign | C13: Cheapest route to −60 °C-class testing. Budget per test campaign rather than buying a freezer outright. | D13: 4 | E13: 2000 | F13: =D13*E13 -> 8000 | I13: Y | J13: Estimate | K13: Industrial gas supplier | L13: To buy
A14: TES-08 | B14: Chest freezer for repeated cold soak | C14: Optional alternative to dry ice if you expect many cold cycles. Reaches roughly −20 °C, not stratospheric, but useful for repeated functional testing. | D14: 1 | E14: 18000 | F14: =D14*E14 -> 18000 | I14: Y | J14: Estimate | K14: Any retailer | L14: Optional
A15: TES-09 | B15: Load cell and lift measurement rig | C15: Measures neck lift on fill day. Guessing the fill is how balloons burst low or ascend too slowly. | D15: 1 | E15: 3500 | F15: =D15*E15 -> 3500 | I15: Y | J15: Estimate | K15: Local / electronics | L15: To buy
A16: TES-10 | B16: Anemometer and weather instruments | C16: Launch-day go/no-go decisions at the site. | D16: 1 | E16: 3000 | F16: =D16*E16 -> 3000 | I16: Y | J16: Estimate | K16: Any retailer | L16: To buy
A17: TES-11 | B17: Gas handling safety kit: gloves, goggles, trolley, first aid | C17: Compressed gas cylinders are the most immediately dangerous thing in this entire programme. | D17: 1 | E17: 5000 | F17: =D17*E17 -> 5000 | I17: Y | J17: Estimate | K17: Safety supplier | L17: To buy
A18: TOTAL | F18: =SUM(F6:F17) -> 117000 | H18: =SUM(H6:H17) -> 0
A19: OF WHICH FLIES | H19: =SUMIF(I6:I17,"Y",H6:H17) -> 0 | J19: This is the mass that sizes the balloon.

Sheet Per flight costs
A1: PER-FLIGHT RECURRING COSTS
A2: Excludes the balloon and gas, which are listed on the version 1 and version 2 sheets. Multiply this sheet by the number of launch attempts, not the number of flights you plan.
A4: Ref | B4: Item | C4: Why this one / spec | D4: Qty | E4: Unit cost (INR) | F4: Line cost (INR) | G4: Mass each (g) | H4: Line mass (g) | I4: Flies? | J4: Price basis | K4: Where to buy | L4: Status
A5: PER FLIGHT — recurring, and the reason a lost payload hurts twice
A6: PER-01 | B6: Chase vehicle fuel and tolls | C6: Gujarat, planning for a recovery drive of up to 200 km each way. The published glider flew 196 km from a 10 km release. | D6: 1 | E6: 4500 | F6: =D6*E6 -> 4500 | I6: Y | J6: Range verified from published glider flight | K6: — | L6: Per flight
A7: PER-02 | B7: Satellite tracker airtime | C7: Monthly plan plus per-message cost. Verify current pricing when you buy the hardware. | D7: 2 | E7: 2000 | F7: =D7*E7 -> 4000 | I7: Y | J7: Estimate — verify with provider | K7: Provider | L7: Per flight
A8: PER-03 | B8: Mobile data and connectivity for the field team | C8: Live tracking and prediction updates from the launch site. | D8: 1 | E8: 1000 | F8: =D8*E8 -> 1000 | I8: Y | J8: Estimate | K8: — | L8: Per flight
A9: PER-04 | B9: Consumables: tape, cord, cable ties, batteries | C9: Replaced every flight. | D9: 1 | E9: 3000 | F9: =D9*E9 -> 3000 | I9: Y | J9: Estimate | K9: Local | L9: Per flight
A10: PER-05 | B10: Contingency for a second launch attempt | C10: Weather scrubs happen. Budget for travelling to the site and not launching. | D10: 1 | E10: 5000 | F10: =D10*E10 -> 5000 | I10: Y | J10: Allowance | K10: — | L10: Per flight
A11: TOTAL | F11: =SUM(F6:F10) -> 17500 | H11: =SUM(H6:H10) -> 0
A12: OF WHICH FLIES | H12: =SUMIF(I6:I10,"Y",H6:H10) -> 0 | J12: This is the mass that sizes the balloon.

Sheet Fees and permissions
A1: FEES, LICENCES AND PERMISSIONS
A2: These cost little and take the longest. Two of them gate the flight entirely: the radio licence decides what link you may legally run, and the DGCA permission decides whether you may fly at all.
A4: Ref | B4: Item | C4: Why this one / spec | D4: Qty | E4: Unit cost (INR) | F4: Line cost (INR) | G4: Mass each (g) | H4: Line mass (g) | I4: Flies? | J4: Price basis | K4: Where to buy | L4: Status
A5: PERMISSIONS AND FEES — the longest-lead items in the programme
A6: FEE-01 | B6: Amateur radio licence: ASOC exam and licence fee | C6: The exam is a 100-mark written paper plus a Morse test, except for the Restricted grade. After passing there is police verification, and the process takes a few months. | D6: 1 | E6: 2000 | F6: =D6*E6 -> 2000 | I6: Y | J6: Verified: Indian amateur licensing information (VU2MSY) | K6: WPC, Ministry of Communications | L6: To start
A7: FEE-02 | B7: Equipment Type Approval, if required | C7: ETA is a self-declaration process on the Saral Sanchar portal for licence-free band equipment, reported at ₹10,000 per model. | D7: 1 | E7: 10000 | F7: =D7*E7 -> 10000 | I7: Y | J7: Verified: reported ETA fee, to be confirmed on the portal | K7: DoT Saral Sanchar | L7: To verify
A8: FEE-03 | B8: RF test report for ETA, if required | C8: Only if you must certify a module yourself. Verify necessity first, because this line is large. | D8: 1 | E8: 0 | F8: =D8*E8 -> 0 | I8: Y | J8: Left at zero pending the ETA question | K8: Accredited lab | L8: To verify
A9: FEE-04 | B9: DGCA notification for an unmanned free balloon | C9: Notification and NOTAM process, plus airspace coordination. A powered return changes how the application is read. | D9: 1 | E9: 5000 | F9: =D9*E9 -> 5000 | I9: Y | J9: Estimate — fees to be confirmed with DGCA | K9: DGCA | L9: To start
A10: FEE-05 | B10: Local and district permissions, launch site | C10: Police and district administration, plus any landowner agreement at the site. | D10: 1 | E10: 5000 | F10: =D10*E10 -> 5000 | I10: Y | J10: Estimate | K10: Local authorities | L10: To start
A11: FEE-06 | B11: Third-party liability insurance | C11: Ask for a quote early. The answer also tells you how an underwriter reads your risk. | D11: 1 | E11: 15000 | F11: =D11*E11 -> 15000 | I11: Y | J11: Estimate — obtain a quote | K11: Insurer | L11: To verify
A12: TOTAL | F12: =SUM(F6:F11) -> 37000 | H12: =SUM(H6:H11) -> 0
A13: OF WHICH FLIES | H13: =SUMIF(I6:I11,"Y",H6:H11) -> 0 | J13: This is the mass that sizes the balloon.

Sheet Rules and findings
A1: WHAT CHANGES THE BOM — READ BEFORE BUYING
B3: Findings that would cost you a payload
B4: The radio licence gates the whole link design | C4: A published amateur build sent 640x480 video at 12 fps from a balloon using 1 W of FSK on the 70 cm band with LDPC coding, received past 50 km. In India, 1 W on 433 MHz is amateur-band operation. The licence-free allowance in 433-434.79 MHz is about 10 mW ERP, a hundred times less power. The amateur route means the ASOC exam, and the Restricted grade permits voice only, which does not cover a data downlink. Digital privileges need a higher grade, and Grade I requires a Morse test. After passing there is police verification, which takes months. Start this in month 1. It is the longest-lead item in the programme and it decides what link you may legally fly.
B5: Licence-free telemetry works, but the duty cycle does not allow video | C5: India permits up to 500 mW ERP in 865-868 MHz for tracking, tracing and data acquisition, with adaptive power control mandatory and a 2.5% duty cycle. That is ample for position and housekeeping telemetry and nowhere near enough for live video. Note also that the Indian band tops out at 868 MHz, so the standard European LoRa channels at 868.1, 868.3 and 868.5 MHz fall outside it. Use the India 865-867 plan.
B6: Your GPS probably works, but prove it | C6: I expected the NEO-7M to stop at the 18 km export-control limit. Checking it, the u-blox 6/7/8 family combines its altitude and speed limits with AND logic, so it keeps reporting above 18 km as long as speed stays under 515 m/s, and is rated to about 50 km in flight mode. The real risk is that clone boards do not persist the airborne dynamic model across a power cycle. Test it: set airborne mode, power cycle, confirm it still reports. Buy one known-good module as primary and keep yours as secondary.
B7: A barometer rated for aviation is not rated for the stratosphere | C7: Pressure at 35 km is about 5 to 6 hPa. A common BMP280 bottoms out near 300 hPa, which is roughly 9 km, so it would stop reading about a quarter of the way up. Specify the minimum pressure from the datasheet rather than an altitude claim in a product listing. This is the most commonly mis-specified part on a balloon payload.
B8: Your servos and propeller are sized for the wrong air | C8: MG996R servos are not rated for stratospheric cold and weigh about 55 g each. Use them for bench and drop testing, and buy cold-rated servos for flight. Separately, air at 10 km is roughly a quarter of sea-level density, so your A2212 with a 1045 propeller will not produce the thrust it does on the bench. Expect a larger diameter and a higher pitch, and test at altitude-equivalent loading rather than assuming.
B9: The finding that challenges version 1 as specified
B10: Returning to base from 35 km is the highest-risk requirement in the programme | C10: A documented autonomous glider flight aimed for a 30 km release and settled for 10 km, because forecast stratospheric winds would have carried the vehicle hundreds of miles out over the ocean. From its 10 km release it still flew about 196 km in a little over two hours, at a top speed near 95 m/s, and landed roughly 10 m from its target waypoint. It used a Pixhawk commanded over MAVLink by a Raspberry Pi Zero, weighed about 1300 g, and the team made six drop tests from a quadcopter before flying it. Two things follow. First, the glide approach works and is proven, which answers your doubt about it. Second, the wind problem at 35 km is real and was enough to make an experienced team lower their release altitude by two thirds. Your version 1 asks for 35 km and a powered return to the launch point. That is a harder problem than the documented precedent, on a first flight. Recommendation: fly a tracker-only shakedown first. It costs a balloon, gas and a few thousand rupees of tracker, and it tells you what the winds over Gujarat actually do to a descending payload. Then commit the expensive vehicle.
B11: How to read the prices in this workbook
B12: Three figures are grounded, the rest are estimates | C12: Grounded: helium at about 2,300 rupees for a 7 cubic metre balloon-grade cylinder, from a current Indian supplier listing. The radio architecture and the glider architecture, both from published builds named above. Everything else is a planning estimate, marked as such in the price basis column. Re-quote before ordering, and expect import duty and shipping on anything not available in India.
B13: Two lines are deliberately left at zero | C13: The RF test report on the fees sheet, and the antenna rotator on the ground station sheet. Both are real possible costs that should not be budgeted until a question is answered: whether you need your own type approval at all, and whether manual antenna tracking actually limits you. Filling in a guess for either would make the rollup look more certain than it is.
B14: Mass is the number that moves the budget | C14: The balloon and its gas are the largest consumable, and balloon size follows from payload mass. An extra 500 g can push you up a balloon size and add a cylinder of helium. Weigh parts as they arrive and keep the mass column current. Separate the flying payload mass from the lift and recovery hardware when you build the real budget; the version 1 sheet totals them together.
B15: Where this connects to the study plan
B16: The BOM is module 5 and module 6 made physical | C16: M05-B01 is building a mass budget with margin per item. M06-C01 to M06-C03 are the energy balance. M07-B05 is the link budget that decides whether your downlink can carry what your camera produces. M19-D01 to M19-D04 are the budget-constrained environmental tests this workbook funds. Do not finalise any of these numbers before you have worked through those modules. The point of the plan is that you can defend each figure yourself.
